[2025-04-23T00:54:13.181+0000] {taskinstance.py:1979} INFO - Dependencies all met for dep_context=non-requeueable deps ti=<TaskInstance: etl_dwh_mart.mart_gsheet manual__2025-04-23T00:54:00.378262+00:00 [queued]>
[2025-04-23T00:54:13.196+0000] {taskinstance.py:1979} INFO - Dependencies all met for dep_context=requeueable deps ti=<TaskInstance: etl_dwh_mart.mart_gsheet manual__2025-04-23T00:54:00.378262+00:00 [queued]>
[2025-04-23T00:54:13.196+0000] {taskinstance.py:2193} INFO - Starting attempt 1 of 1
[2025-04-23T00:54:13.220+0000] {taskinstance.py:2217} INFO - Executing <Task(PythonOperator): mart_gsheet> on 2025-04-23 00:54:00.378262+00:00
[2025-04-23T00:54:13.230+0000] {standard_task_runner.py:60} INFO - Started process 324 to run task
[2025-04-23T00:54:13.236+0000] {standard_task_runner.py:87} INFO - Running: ['***', 'tasks', 'run', 'etl_dwh_mart', 'mart_gsheet', 'manual__2025-04-23T00:54:00.378262+00:00', '--job-id', '19', '--raw', '--subdir', 'DAGS_FOLDER/dags_etl.py', '--cfg-path', '/tmp/tmpmbtj4ugp']
[2025-04-23T00:54:13.238+0000] {standard_task_runner.py:88} INFO - Job 19: Subtask mart_gsheet
[2025-04-23T00:54:13.315+0000] {task_command.py:423} INFO - Running <TaskInstance: etl_dwh_mart.mart_gsheet manual__2025-04-23T00:54:00.378262+00:00 [running]> on host a896c9815708
[2025-04-23T00:54:13.446+0000] {taskinstance.py:2513} INFO - Exporting env vars: AIRFLOW_CTX_DAG_OWNER='***' AIRFLOW_CTX_DAG_ID='etl_dwh_mart' AIRFLOW_CTX_TASK_ID='mart_gsheet' AIRFLOW_CTX_EXECUTION_DATE='2025-04-23T00:54:00.378262+00:00' AIRFLOW_CTX_TRY_NUMBER='1' AIRFLOW_CTX_DAG_RUN_ID='manual__2025-04-23T00:54:00.378262+00:00'
[2025-04-23T00:54:13.448+0000] {Mart_GoogleSheet.py:91} INFO - Processing worksheet: Sheet1
[2025-04-23T00:54:13.450+0000] {Mart_GoogleSheet.py:35} INFO - Extracting data using query: SELECT * FROM mart_user_purchase;
[2025-04-23T00:54:13.487+0000] {Mart_GoogleSheet.py:38} INFO - Data extraction successful
[2025-04-23T00:54:13.489+0000] {Mart_GoogleSheet.py:67} ERROR - Error loading data into worksheet 'Sheet1': [Errno 2] No such file or directory: 'credential.json'
[2025-04-23T00:54:13.490+0000] {Mart_GoogleSheet.py:68} ERROR - Traceback (most recent call last):
  File "/opt/***/script_etl/Mart_GoogleSheet.py", line 49, in load_to_google_sheet
    with open('credential.json','rb') as file:
FileNotFoundError: [Errno 2] No such file or directory: 'credential.json'

[2025-04-23T00:54:13.490+0000] {Mart_GoogleSheet.py:96} ERROR - Failed to process Sheet1: [Errno 2] No such file or directory: 'credential.json'
[2025-04-23T00:54:13.491+0000] {Mart_GoogleSheet.py:91} INFO - Processing worksheet: Sheet2
[2025-04-23T00:54:13.491+0000] {Mart_GoogleSheet.py:35} INFO - Extracting data using query: SELECT * FROM mart_user_repurchase;
[2025-04-23T00:54:13.513+0000] {Mart_GoogleSheet.py:38} INFO - Data extraction successful
[2025-04-23T00:54:13.514+0000] {Mart_GoogleSheet.py:67} ERROR - Error loading data into worksheet 'Sheet2': [Errno 2] No such file or directory: 'credential.json'
[2025-04-23T00:54:13.514+0000] {Mart_GoogleSheet.py:68} ERROR - Traceback (most recent call last):
  File "/opt/***/script_etl/Mart_GoogleSheet.py", line 49, in load_to_google_sheet
    with open('credential.json','rb') as file:
FileNotFoundError: [Errno 2] No such file or directory: 'credential.json'

[2025-04-23T00:54:13.515+0000] {Mart_GoogleSheet.py:96} ERROR - Failed to process Sheet2: [Errno 2] No such file or directory: 'credential.json'
[2025-04-23T00:54:13.515+0000] {Mart_GoogleSheet.py:91} INFO - Processing worksheet: Sheet3
[2025-04-23T00:54:13.515+0000] {Mart_GoogleSheet.py:35} INFO - Extracting data using query: SELECT * FROM mart_revenue_period;
[2025-04-23T00:54:13.541+0000] {Mart_GoogleSheet.py:38} INFO - Data extraction successful
[2025-04-23T00:54:13.541+0000] {Mart_GoogleSheet.py:67} ERROR - Error loading data into worksheet 'Sheet3': [Errno 2] No such file or directory: 'credential.json'
[2025-04-23T00:54:13.542+0000] {Mart_GoogleSheet.py:68} ERROR - Traceback (most recent call last):
  File "/opt/***/script_etl/Mart_GoogleSheet.py", line 49, in load_to_google_sheet
    with open('credential.json','rb') as file:
FileNotFoundError: [Errno 2] No such file or directory: 'credential.json'

[2025-04-23T00:54:13.542+0000] {Mart_GoogleSheet.py:96} ERROR - Failed to process Sheet3: [Errno 2] No such file or directory: 'credential.json'
[2025-04-23T00:54:13.542+0000] {python.py:202} INFO - Done. Returned value was: None
[2025-04-23T00:54:13.557+0000] {taskinstance.py:1149} INFO - Marking task as SUCCESS. dag_id=etl_dwh_mart, task_id=mart_gsheet, execution_date=20250423T005400, start_date=20250423T005413, end_date=20250423T005413
[2025-04-23T00:54:13.609+0000] {local_task_job_runner.py:234} INFO - Task exited with return code 0
[2025-04-23T00:54:13.638+0000] {taskinstance.py:3312} INFO - 0 downstream tasks scheduled from follow-on schedule check
