[2025-04-23T00:53:12.237+0000] {taskinstance.py:1979} INFO - Dependencies all met for dep_context=non-requeueable deps ti=<TaskInstance: etl_dwh_mart.oltp_dwh manual__2025-04-23T00:53:09.646891+00:00 [queued]>
[2025-04-23T00:53:12.252+0000] {taskinstance.py:1979} INFO - Dependencies all met for dep_context=requeueable deps ti=<TaskInstance: etl_dwh_mart.oltp_dwh manual__2025-04-23T00:53:09.646891+00:00 [queued]>
[2025-04-23T00:53:12.252+0000] {taskinstance.py:2193} INFO - Starting attempt 1 of 1
[2025-04-23T00:53:12.277+0000] {taskinstance.py:2217} INFO - Executing <Task(PythonOperator): oltp_dwh> on 2025-04-23 00:53:09.646891+00:00
[2025-04-23T00:53:12.288+0000] {standard_task_runner.py:60} INFO - Started process 273 to run task
[2025-04-23T00:53:12.297+0000] {standard_task_runner.py:87} INFO - Running: ['***', 'tasks', 'run', 'etl_dwh_mart', 'oltp_dwh', 'manual__2025-04-23T00:53:09.646891+00:00', '--job-id', '5', '--raw', '--subdir', 'DAGS_FOLDER/dags_etl.py', '--cfg-path', '/tmp/tmpltusionq']
[2025-04-23T00:53:12.302+0000] {standard_task_runner.py:88} INFO - Job 5: Subtask oltp_dwh
[2025-04-23T00:53:12.403+0000] {task_command.py:423} INFO - Running <TaskInstance: etl_dwh_mart.oltp_dwh manual__2025-04-23T00:53:09.646891+00:00 [running]> on host a896c9815708
[2025-04-23T00:53:12.554+0000] {taskinstance.py:2513} INFO - Exporting env vars: AIRFLOW_CTX_DAG_OWNER='***' AIRFLOW_CTX_DAG_ID='etl_dwh_mart' AIRFLOW_CTX_TASK_ID='oltp_dwh' AIRFLOW_CTX_EXECUTION_DATE='2025-04-23T00:53:09.646891+00:00' AIRFLOW_CTX_TRY_NUMBER='1' AIRFLOW_CTX_DAG_RUN_ID='manual__2025-04-23T00:53:09.646891+00:00'
[2025-04-23T00:53:12.556+0000] {oltpTrans_DWH.py:85} INFO - Starting ETL Process...
[2025-04-23T00:53:12.557+0000] {oltpTrans_DWH.py:36} INFO - Config validation passed
[2025-04-23T00:53:12.557+0000] {oltpTrans_DWH.py:41} INFO - Extracting data from tb_users...
[2025-04-23T00:53:12.563+0000] {oltpTrans_DWH.py:46} ERROR - Error extracting data from tb_users: (psycopg2.OperationalError) connection to server at "localhost" (::1), port 5432 failed: Connection refused
	Is the server running on that host and accepting TCP/IP connections?
connection to server at "localhost" (127.0.0.1), port 5432 failed: Connection refused
	Is the server running on that host and accepting TCP/IP connections?

(Background on this error at: https://sqlalche.me/e/14/e3q8)
[2025-04-23T00:53:12.564+0000] {oltpTrans_DWH.py:93} ERROR - ETL process failed: (psycopg2.OperationalError) connection to server at "localhost" (::1), port 5432 failed: Connection refused
	Is the server running on that host and accepting TCP/IP connections?
connection to server at "localhost" (127.0.0.1), port 5432 failed: Connection refused
	Is the server running on that host and accepting TCP/IP connections?

(Background on this error at: https://sqlalche.me/e/14/e3q8)
[2025-04-23T00:53:12.565+0000] {python.py:202} INFO - Done. Returned value was: None
[2025-04-23T00:53:12.581+0000] {taskinstance.py:1149} INFO - Marking task as SUCCESS. dag_id=etl_dwh_mart, task_id=oltp_dwh, execution_date=20250423T005309, start_date=20250423T005312, end_date=20250423T005312
[2025-04-23T00:53:12.630+0000] {local_task_job_runner.py:234} INFO - Task exited with return code 0
[2025-04-23T00:53:12.705+0000] {taskinstance.py:3312} INFO - 0 downstream tasks scheduled from follow-on schedule check
