[2025-04-23T00:53:19.577+0000] {taskinstance.py:1979} INFO - Dependencies all met for dep_context=non-requeueable deps ti=<TaskInstance: etl_dwh_mart.dwh_mart_revenue_period manual__2025-04-23T00:53:09.646891+00:00 [queued]>
[2025-04-23T00:53:19.600+0000] {taskinstance.py:1979} INFO - Dependencies all met for dep_context=requeueable deps ti=<TaskInstance: etl_dwh_mart.dwh_mart_revenue_period manual__2025-04-23T00:53:09.646891+00:00 [queued]>
[2025-04-23T00:53:19.601+0000] {taskinstance.py:2193} INFO - Starting attempt 1 of 1
[2025-04-23T00:53:19.634+0000] {taskinstance.py:2217} INFO - Executing <Task(PythonOperator): dwh_mart_revenue_period> on 2025-04-23 00:53:09.646891+00:00
[2025-04-23T00:53:19.645+0000] {standard_task_runner.py:60} INFO - Started process 290 to run task
[2025-04-23T00:53:19.652+0000] {standard_task_runner.py:87} INFO - Running: ['***', 'tasks', 'run', 'etl_dwh_mart', 'dwh_mart_revenue_period', 'manual__2025-04-23T00:53:09.646891+00:00', '--job-id', '11', '--raw', '--subdir', 'DAGS_FOLDER/dags_etl.py', '--cfg-path', '/tmp/tmpdehh5spj']
[2025-04-23T00:53:19.655+0000] {standard_task_runner.py:88} INFO - Job 11: Subtask dwh_mart_revenue_period
[2025-04-23T00:53:19.738+0000] {task_command.py:423} INFO - Running <TaskInstance: etl_dwh_mart.dwh_mart_revenue_period manual__2025-04-23T00:53:09.646891+00:00 [running]> on host a896c9815708
[2025-04-23T00:53:19.872+0000] {taskinstance.py:2513} INFO - Exporting env vars: AIRFLOW_CTX_DAG_OWNER='***' AIRFLOW_CTX_DAG_ID='etl_dwh_mart' AIRFLOW_CTX_TASK_ID='dwh_mart_revenue_period' AIRFLOW_CTX_EXECUTION_DATE='2025-04-23T00:53:09.646891+00:00' AIRFLOW_CTX_TRY_NUMBER='1' AIRFLOW_CTX_DAG_RUN_ID='manual__2025-04-23T00:53:09.646891+00:00'
[2025-04-23T00:53:19.874+0000] {DWH_MartRevenuePeriod.py:30} INFO - Extracting data using query: 
            SELECT order_date, order_total
            FROM fact_orders;
        
[2025-04-23T00:53:19.875+0000] {DWH_MartRevenuePeriod.py:36} ERROR - Error extracting data: (psycopg2.OperationalError) connection to server at "localhost" (::1), port 5432 failed: Connection refused
	Is the server running on that host and accepting TCP/IP connections?
connection to server at "localhost" (127.0.0.1), port 5432 failed: Connection refused
	Is the server running on that host and accepting TCP/IP connections?

(Background on this error at: https://sqlalche.me/e/14/e3q8)
[2025-04-23T00:53:19.876+0000] {DWH_MartRevenuePeriod.py:77} ERROR - process failed: (psycopg2.OperationalError) connection to server at "localhost" (::1), port 5432 failed: Connection refused
	Is the server running on that host and accepting TCP/IP connections?
connection to server at "localhost" (127.0.0.1), port 5432 failed: Connection refused
	Is the server running on that host and accepting TCP/IP connections?

(Background on this error at: https://sqlalche.me/e/14/e3q8)
[2025-04-23T00:53:19.877+0000] {python.py:202} INFO - Done. Returned value was: None
[2025-04-23T00:53:19.892+0000] {taskinstance.py:1149} INFO - Marking task as SUCCESS. dag_id=etl_dwh_mart, task_id=dwh_mart_revenue_period, execution_date=20250423T005309, start_date=20250423T005319, end_date=20250423T005319
[2025-04-23T00:53:19.945+0000] {local_task_job_runner.py:234} INFO - Task exited with return code 0
[2025-04-23T00:53:19.998+0000] {taskinstance.py:3312} INFO - 1 downstream tasks scheduled from follow-on schedule check
